#VRML_SIM R2023a utf8

EXTERNPROTO "https://raw.githubusercontent.com/cyberbotics/webots/R2023a/projects/objects/backgrounds/protos/TexturedBackground.proto"
EXTERNPROTO "https://raw.githubusercontent.com/cyberbotics/webots/R2023a/projects/objects/floors/protos/Floor.proto"
EXTERNPROTO "https://raw.githubusercontent.com/cyberbotics/webots/R2023a/projects/appearances/protos/ThreadMetalPlate.proto"
EXTERNPROTO "https://raw.githubusercontent.com/cyberbotics/webots/R2023a/projects/objects/apartment_structure/protos/Door.proto"
EXTERNPROTO "https://raw.githubusercontent.com/cyberbotics/webots/R2023a/projects/appearances/protos/GlossyPaint.proto"
EXTERNPROTO "https://raw.githubusercontent.com/cyberbotics/webots/R2023a/projects/objects/obstacles/protos/OilBarrel.proto"
EXTERNPROTO "https://raw.githubusercontent.com/cyberbotics/webots/R2023a/projects/objects/factory/pipes/protos/LJoint.proto"
EXTERNPROTO "https://raw.githubusercontent.com/cyberbotics/webots/R2023a/projects/objects/factory/tools/protos/Wrench.proto"
EXTERNPROTO "https://raw.githubusercontent.com/cyberbotics/webots/R2023a/projects/objects/factory/tools/protos/Hammer.proto"
EXTERNPROTO "https://raw.githubusercontent.com/cyberbotics/webots/R2023a/projects/objects/factory/pallet/protos/WoodenPallet.proto"
EXTERNPROTO "https://raw.githubusercontent.com/cyberbotics/webots/R2023a/projects/objects/tables/protos/Table.proto"
EXTERNPROTO "https://raw.githubusercontent.com/cyberbotics/webots/R2023a/projects/objects/factory/containers/protos/CardboardBox.proto"
EXTERNPROTO "https://raw.githubusercontent.com/cyberbotics/webots/R2023a/projects/objects/factory/tools/protos/PaintBucket.proto"
EXTERNPROTO "https://raw.githubusercontent.com/cyberbotics/webots/R2023a/projects/objects/factory/tools/protos/Screwdriver.proto"
EXTERNPROTO "https://raw.githubusercontent.com/cyberbotics/webots/R2023a/projects/objects/factory/pallet/protos/WoodenPalletStack.proto"
EXTERNPROTO "https://raw.githubusercontent.com/cyberbotics/webots/R2023a/projects/objects/factory/containers/protos/WoodenBox.proto"
EXTERNPROTO "https://raw.githubusercontent.com/cyberbotics/webots/R2023a/projects/objects/factory/valves/protos/LeverValve.proto"
EXTERNPROTO "https://raw.githubusercontent.com/cyberbotics/webots/R2023a/projects/objects/factory/valves/protos/LargeValve.proto"
EXTERNPROTO "https://raw.githubusercontent.com/cyberbotics/webots/R2023a/projects/objects/factory/pipes/protos/PipeSection.proto"
EXTERNPROTO "https://raw.githubusercontent.com/cyberbotics/webots/R2023a/projects/objects/factory/valves/protos/SmallValve.proto"
EXTERNPROTO "https://raw.githubusercontent.com/cyberbotics/webots/R2023a/projects/objects/apartment_structure/protos/Wall.proto"
EXTERNPROTO "https://raw.githubusercontent.com/cyberbotics/webots/R2023a/projects/appearances/protos/Roughcast.proto"
EXTERNPROTO "https://raw.githubusercontent.com/cyberbotics/webots/R2023a/projects/objects/cabinet/protos/Cabinet.proto"
EXTERNPROTO "https://raw.githubusercontent.com/cyberbotics/webots/R2023a/projects/objects/hospital/protos/EmergencyExitSign.proto"
EXTERNPROTO "https://raw.githubusercontent.com/cyberbotics/webots/R2023a/projects/objects/stairs/protos/StraightStairsRail.proto"
EXTERNPROTO "https://raw.githubusercontent.com/cyberbotics/webots/R2023a/projects/objects/stairs/protos/StraightStairs.proto"

WorldInfo {
}
Viewpoint {
  orientation -0.3096485222886867 0.8270379269534006 0.46917593717608164 1.2671955401835018
  position -4.287350707422629 -8.413466673121656 18.915703009762453
}
TexturedBackground {
  texture "empty_office"
}
PointLight {
  attenuation 0 0 1
  intensity 10.8
  location -4 6 5
  castShadows TRUE
}
PointLight {
  attenuation 0 0 1
  intensity 9.6
  location 5 6 5
}
Floor {
  translation 0 -4.3 0
  name "floor(1)"
  size 20 16.4
  tileSize 1 1
  appearance ThreadMetalPlate {
  }
}
Door {
  hidden translation_5 0.0010000021580102714 6.769338423140425e-10 0
  translation 10.04 -4 3.27
  rotation 0 0 1 3.141592
  name "door(1)"
  position -3.973656812940865e-09
  doorAppearance GlossyPaint {
    baseColor 0.16 0.16 0.16
  }
  frameAppearance GlossyPaint {
    baseColor 0.35 0.3503166247043564 0.35
  }
}
OilBarrel {
  translation 9.337425 2.8961435 0.44
  rotation 0 0 1 2.87325
  name "oil barrel(1)"
}
OilBarrel {
  translation 8.4218847 2.1373536 0.44
  rotation 0 0 1 2.87325
  name "oil barrel(2)"
}
OilBarrel {
  translation 8.2750954 3.0222101 0.44
  rotation 0 0 1 -0.340335
}
Door {
  hidden translation_5 0.0010000021580102159 6.769337312917401e-10 0
  translation -10.05 0 0.02
  position -3.973656755432705e-09
  doorAppearance GlossyPaint {
    baseColor 0.16 0.16 0.16
  }
  frameAppearance GlossyPaint {
    baseColor 0.35 0.3503166247043564 0.35
  }
}
Floor {
  translation 0 -4.22 7
  rotation 1 0 0 3.141592
  size 20 16.4
  tileSize 1 1
  appearance PBRAppearance {
    baseColorMap ImageTexture {
      url [
        "https://raw.githubusercontent.com/cyberbotics/webots/R2023a/projects/default/worlds/textures/asphalt.jpg"
      ]
    }
    roughness 1
    metalness 0
  }
}
LJoint {
  translation -7.571 3.19 0.712
  rotation 0 0 1 -1.5708
  name "L joint pipe(1)"
}
LJoint {
  translation -7.571 3.277 2.422
  rotation -0.577350278331609 0.577350264618634 0.577350264618634 2.094395086923155
}
Wrench {
  translation -0.3584810292754445 -4.3481352034649206 0.7387777668704228
  rotation -0.00023488582147755625 -0.0001760995823751107 -0.999999956908793 1.566742281328162
  name "wrench(1)"
}
Wrench {
  translation 0.8606644852001574 -4.69669562105236 0.7387777668704233
  rotation 0.00021382792756301358 3.097919903365085e-05 0.9999999766589531 -2.565635354947457
}
Hammer {
  translation -0.8077838871285566 -4.680486961378801 0.7524935805881866
  rotation -0.005005348031888967 0.003295734196740518 -0.99998204215235 2.0943901841343755
  name "hammer(1)"
}
Hammer {
  translation 1.5252412004686653 -4.88839543281043 0.7524935805881866
  rotation 0.00040528069579485836 -0.005602986114308127 0.9999842210225921 2.3562183586627024
}
WoodenPallet {
  translation -3.05 -12.1 0.52
  rotation 0.44721372362178063 0.44721372362178063 0.7745965212991105 -1.82348
}
Table {
  translation -0.23882837 -4.8402928 0
  size 4.5 1.5 0.74
}
CardboardBox {
  translation 2.2324987 -11.807743 0.31
  rotation 0 0 1 -1.5707963267948966
}
PaintBucket {
  hidden position_0_0 -0.3194813164914134
  hidden linearVelocity_0 6.625567255043517e-05 9.199099262744616e-05 -0.0002628996868124347
  hidden angularVelocity_0 -0.0025282651379281967 0.0018209812629882262 4.1426879830408586e-10
  hidden rotation_1 0 -1 0 2.3374463664906746
  hidden position_1_0 0.43975993708094147
  hidden linearVelocity_1 0.00015950194114679075 0.00022145721416816187 -8.577737712442289e-05
  hidden angularVelocity_1 -0.0025281478077075043 0.0018209141339192143 5.374479686892524e-10
  hidden rotation_2 0 1 0 0.43975993708094135
  hidden linearVelocity_2 9.535595690612943e-05 0.00013239993830900347 2.4880727987981765e-05
  hidden angularVelocity_2 -0.002514810582937294 0.0018132142858148625 2.1393670857842127e-09
  translation -0.7214549395800559 -5.177764909996788 0.738375331089216
  rotation 0.002975690823996875 -0.005157474815712868 0.999982272701694 1.047213948896309
}
Screwdriver {
  translation -0.07117697826782886 -5.200919723905924 0.7518493098684723
  rotation -0.001014603768656373 0.0006132404949444436 0.999999297257397 2.0935974926817447
}
WoodenPalletStack {
  translation -6.8424942 -11.754332 0
  name "wooden pallet stack(1)"
  palletNumber 6
}
WoodenPalletStack {
  translation -5.2560137 -11.74814 0
  palletNumber 20
}
WoodenBox {
  translation 7.03 0.928 0.3
  rotation -0.935113119114731 0.250562820924732 0.250562820924732 4.645351474266668
  name "wooden box(1)"
}
WoodenBox {
  translation 0.14546116 -11.909219 0.3
  rotation 1 0 0 1.5707963267948966
  name "wooden box(2)"
}
WoodenBox {
  translation -1.1321262 -11.1489 0.3
  rotation 0.862856210520177 0.357406743058074 0.357406743058073 1.71777151624413
  name "wooden box(3)"
}
WoodenBox {
  translation 1.5463886 -11.768592 0.3
  rotation 1 0 0 1.5707963267948966
  name "wooden box(4)"
}
WoodenBox {
  translation -0.49883855 -11.765703 0.3
  rotation 1 0 0 1.5707963267948966
  name "wooden box(5)"
}
WoodenBox {
  translation 0.95220994 -10.946614 0.3
  rotation -0.677661491465059 0.519987933987584 0.519987933987584 4.332744312017075
  name "wooden box(6)"
}
WoodenBox {
  translation 0.91693757 -11.921006 0.3
  rotation 1 0 0 1.5707963267948966
  name "wooden box(7)"
}
WoodenBox {
  translation 0.74212598 -12.012516 0.9
  rotation 1 0 0 1.5707963267948966
  name "wooden box(8)"
}
WoodenBox {
  translation -0.5072975 -11.706525 1.52
  rotation 1 0 0 1.5707963267948966
  name "wooden box(9)"
}
WoodenBox {
  translation -0.48872581 -11.691652 0.93
  rotation 1 0 0 1.5707963267948966
}
LeverValve {
  hidden position_0_0 -1.0402644350741452e-07
  hidden translation_1 0 5.325569688614171e-09 -7.320533068622126e-16
  hidden rotation_1 -1 0 0 2.698715072315163e-07
  translation -7.5791585 3 0.692
  rotation 0 0 1 -1.5708
}
LargeValve {
  hidden position_0_0 -15.70796186546593
  hidden translation_1 1.1102230246251565e-16 1.5356653078497058e-07 1.07705511176448e-13
  hidden rotation_1 1 0 0 1.3911652585248996e-06
  translation -5.7149744 2.9726835 0.706
  rotation 0 0 1 -1.5708
}
PipeSection {
  translation -7.5740452 3 0.18
  name "pipe section(1)"
  height 1.2
}
PipeSection {
  translation -5.2940471 3 0.7
  rotation 0 1 0 1.5708
  name "pipe section(2)"
  height 0.9
  radius 0.02
}
PipeSection {
  translation -7.5720026 3.234 1.56
  name "pipe section(3)"
  height 1.6
}
PipeSection {
  translation -4.8579962 3 0.35
  name "pipe section(4)"
  height 0.7
  radius 0.02
}
PipeSection {
  translation -6.6249962 3 0.70600102
  name "pipe section(5)"
  height 1.7
}
PipeSection {
  translation -7.572 3.74 2.4659975
  rotation 1 0 0 -1.5708
  name "pipe section(6)"
  height 0.8
}
PipeSection {
  translation -5.714996 3.37 0.65600436
  rotation 1 0 0 1.5708
  height 0.8
}
SmallValve {
  hidden position_0_0 -15.706039858481542
  hidden translation_1 0.005999999999999996 -8.131211256257043e-07 -0.020400406540306906
  hidden rotation_1 1 0 0 3.141589541518704
  translation -4.8638332 3 0.707
  rotation 0 0 1 -1.5708
}
Wall {
  translation 0 3.82 0
  name "wall(1)"
  size 20 0.2 7
  appearance Roughcast {
    textureTransform TextureTransform {
      scale 5 1.75
    }
  }
}
Cabinet {
  translation -0.46 3.84 0
  rotation 0 0 1 -1.5707963267948966
  name "cabinet(1)"
  columnsWidths [
    1.3, 0.17, 0.17
  ]
  layout [
    "Shelf (1, 5, 3, 0)"
    "Shelf (1, 4, 3, 0)"
    "Shelf (1, 3, 3, 0)"
    "Shelf (1, 2, 3, 0)"
  ]
}
Cabinet {
  hidden position_6_0 4.355589762375103e-12
  hidden position_10_0 -4.359956843267508e-12
  translation 1.49 3.84 0
  rotation 0 0 1 -1.5707963267948966
  columnsWidths [
    1, 1
  ]
  layout [
    "RightSidedDoor (1, 1, 1, 5, 1.5)"
    "LeftSidedDoor (2, 1, 1, 5, 1.5)"
  ]
}
Wall {
  translation 0 -12.5 0
  name "wall(2)"
  size 20 0.2 7
  appearance Roughcast {
    textureTransform TextureTransform {
      scale 5 1.75
    }
  }
}
Wall {
  translation -10 -4.3 0
  rotation 0 0 1 1.5708
  name "wall(3)"
  size 16.5 0.2 7
  appearance Roughcast {
    textureTransform TextureTransform {
      scale 4.125 1.725
    }
  }
}
Wall {
  translation 10 -4.3 0
  rotation 0 0 1 -1.5708
  size 16.5 0.2 7
  appearance Roughcast {
    textureTransform TextureTransform {
      scale 4.125 1.725
    }
  }
}
EmergencyExitSign {
  translation 9.82 -4.02 5.45
  rotation 0.5773509358560258 -0.577349935856137 -0.577349935856137 2.09439
}
EmergencyExitSign {
  translation -9.83 -0.01 2.3
  rotation 0.5773489358550934 0.5773519358547601 0.5773499358549823 2.0944
  name "emergency exit sign(1)"
}
Solid {
  translation -9.87 -6.36 4.13
  rotation 0.7071067811865476 0 0.7071067811865476 3.141592
  children [
    Shape {
      appearance PBRAppearance {
        baseColor 0.8 0.8 0.8
        baseColorMap ImageTexture {
          url [
            "https://raw.githubusercontent.com/cyberbotics/webots/R2023a/projects/default/worlds/textures/ladybug.png"
          ]
          filtering 5
        }
        transparency 0.6
        roughness 0.5
        metalness 0
        textureTransform TextureTransform {
          rotation 1.5708
        }
      }
      geometry Plane {
        size 5 5
      }
    }
  ]
  name "solid(3)"
}
Solid {
  translation 9.25 -3.95 3.21
  rotation 1 0 0 1.5707963267948966
  children [
    Shape {
      appearance PBRAppearance {
        baseColor 0.8 0.8 0.8
        baseColorMap ImageTexture {
          url [
            "https://raw.githubusercontent.com/cyberbotics/webots/R2023a/projects/default/worlds/textures/steel_floor.jpg"
          ]
        }
        roughness 0.5
        metalness 0
        textureTransform TextureTransform {
          scale 2 2
        }
      }
      geometry Box {
        size 1.5 0.12 2.6
      }
    }
  ]
}
StraightStairsRail {
  translation 8.52 -2.73 3.27
  rotation 0 0 1 -1.5708
  name "straight stairs rail(1)"
  run 2.5
  rise 0
  newelHeight 0.89
  balusterHeight 0.9
  nBalusters 9
  appearance PBRAppearance {
    baseColor 0.8 0.8 0.8
    roughness 0.5
    metalness 0
    textureTransform TextureTransform {
      rotation 1.5708
    }
  }
}
StraightStairsRail {
  translation 8.57 -5.23 3.27
  run 1.3
  rise 0
  newelHeight 0.89
  balusterHeight 0.9
  nBalusters 5
  appearance PBRAppearance {
    baseColor 0.8 0.8 0.8
    roughness 0.5
    metalness 0
    textureTransform TextureTransform {
      rotation 1.5708
    }
  }
}
StraightStairs {
  translation 9.201 0.17 0
  rotation 0 0 1 -1.5708
  stepSize 0.3 1.34 0.01
  stepRise 0.297
  nSteps 10
  stepAppearance PBRAppearance {
    baseColor 0.8 0.8 0.8
    roughness 0.5
    metalness 0
    textureTransform TextureTransform {
      rotation 1.5708
      scale 3 1
    }
  }
  stringerAppearance PBRAppearance {
    baseColor 0.8 0.8 0.8
    roughness 0.5
    metalness 0
    textureTransform TextureTransform {
      rotation 1.5708
      scale 3 3
    }
  }
  leftRail []
  rightRail [
    StraightStairsRail {
      run 3
      rise 2.97
      newelHeight 0.862
      balusterHeight 0.83
      nBalusters 12
      appearance PBRAppearance {
        baseColor 0.8 0.8 0.8
        roughness 0.5
        metalness 0
        textureTransform TextureTransform {
          rotation 1.5708
        }
      }
    }
  ]
}

Robot {
  children [
    HingeJoint {
      jointParameters HingeJointParameters {
        axis 0 1 0
        anchor -0.10 0 0.1
      }
      device [
        RotationalMotor {
          name "left wheel motor"
        }
      ]
      endPoint Solid {
        translation -0.1 0 0.1
        children [
          DEF WHEEL Transform {
            rotation  1 0 0 1.57
            children [
              Shape {
                appearance PBRAppearance {
                  baseColor 1 0 0
                  roughness 1
                  metalness 0
                }
                geometry Cylinder {
                  height 0.05
                  radius 0.1
                }
              }
            ]
          }
        ]
        name "left wheel"
        boundingObject USE WHEEL
        physics Physics {
          density -1
          mass 10
        }
      }
    }
    HingeJoint {
      jointParameters HingeJointParameters {
        axis 0 1 0
        anchor -0.10 0 0.1
      }
      device [
        RotationalMotor {
          name "right wheel motor"
        }
      ]
      endPoint Solid {
        translation -0.1 0.71 0.1
        rotation 1 0 0 0
        children [
          USE WHEEL
        ]
        name "right wheel"
        boundingObject USE WHEEL
        physics Physics {
          density -1
          mass 10
        }
      }
    }  
    DEF AGV Transform {
      translation -0.53 -0.219 0.012
      rotation 0 0 1 1.57
      scale 0.001 0.001 0.001
      children [
          Shape {
          appearance Appearance {
            material Material {
              ambientIntensity 0
              diffuseColor 0.5 0.8 0.8
              emissiveColor 0.5 0.5 0.5
              shininess 0.3
            }
          }
          geometry DEF BODY_AGV Mesh {
            url [
              "agv_simplified.dae"
            ]
          }
          castShadows FALSE
          isPickable FALSE
        }
      ]
    }
    DistanceSensor {
      translation  0.44 0.175 0.323
      children [
        DEF SENSOR Transform {
          rotation 0 1 0 1.5708
          children [
            Shape {
              appearance PBRAppearance {
                baseColor 1 1 0
                roughness 1
                metalness 0
              }
              geometry Cylinder {
                height 0.004
                radius 0.008
              }
            }
          ]
        }
      ]
      name "ds0"
      lookupTable [
        0 1020 0
        0.5 1020 0
        1 100 0
      ]
      numberOfRays 2
      aperture 1
    }
    DistanceSensor {
      translation  0.44 0.54 0.323
      children [
        USE SENSOR
      ]
      name "ds1"
      lookupTable [
        0 1020 0
        0.5 1020 0
        1 100 0
      ]
      numberOfRays 2
      aperture 1
    }
  ]
  boundingObject USE AGV
  physics Physics {
    density -1
    mass 20
  }
  controller "<extern>"
  name "my_robot"
}